Workbook

Sheet 0_Accueil
B2: DASHBOARD BFR
B3: Besoin en Fonds de Roulement — votre pilote de trésorerie
B7: ① VOS PARAMÈTRES (remplissez les cases colorées)
B8: Société | D8: dss | E8: ← Le nom de votre entreprise
B9: Secteur | E9: ← Distribution / Industrie / BTP / Services / Agroalimentaire
B10: Date du jour | D10: 46260 | E10: ← La date d'aujourd'hui (ou date du bilan)
B11: CA annuel HT | E11: ← Votre chiffre d'affaires de l'année, en DH
B12: Taux de TVA | D12: 0.2 | E12: ← Écrivez 0.20 pour 20 % (pas "20")
B13: ⚠ Pour la TVA : écrivez 0.20 (= 20 %). Ce chiffre sert dans TOUS les calculs.
B15: ② COMMENT UTILISER CE FICHIER (3 étapes)
B16: ÉTAPE 1 | D16: Onglet 1_Balance_GL Collez la balance de votre logiciel comptable (Sage, Odoo…). C'est la voie rapide.
B17: ÉTAPE 2 | D17: Onglets 2_Clients & 3_Fournisseurs OU tapez vos factures une par une. C'est plus long, mais bien plus précis.
B18: ÉTAPE 3 | D18: Onglet 5_Dashboard Regardez vos résultats en clair. Tout y est expliqué comme à un débutant.
B20: ③ BOUTONS (nécessitent l'activation des macros)
B21: 📥 Importer la balance (CSV) | D21: ✂ Nettoyer les n° de compte
B22: 🔄 Réinitialiser les données | D22: 📄 Exporter le Dashboard (PDF)
B23: → Fichier → Options → Centre de gestion de la confidentialité → Activer les macros.

Sheet 1_Balance_GL
A1: 1 · BALANCE GÉNÉRALE — collez ici l'export de votre logiciel comptable
A2: Collez vos comptes dans les colonnes A à D (lignes 8 à 207). La colonne E (Solde) se calcule seule. Si les totaux du bas affichent 0 : vos numéros de compte contiennent des espaces → bouton « Nettoyer ».
A3: Depuis Sage : Comptabilité → Balance générale → Exporter (N°Compte | Libellé | Débit | Crédit)
A7: N° Compte | B7: Libellé du compte | C7: Débit (DH) | D7: Crédit (DH) | E7: Solde (auto)
E8: =IF(AND(C8="",D8=""),"",C8-D8)
E9: =IF(AND(C9="",D9=""),"",C9-D9)
E10: =IF(AND(C10="",D10=""),"",C10-D10)
E11: =IF(AND(C11="",D11=""),"",C11-D11)
E12: =IF(AND(C12="",D12=""),"",C12-D12)
E13: =IF(AND(C13="",D13=""),"",C13-D13)
E14: =IF(AND(C14="",D14=""),"",C14-D14)
E15: =IF(AND(C15="",D15=""),"",C15-D15)
E16: =IF(AND(C16="",D16=""),"",C16-D16)
E17: =IF(AND(C17="",D17=""),"",C17-D17)
E18: =IF(AND(C18="",D18=""),"",C18-D18)
E19: =IF(AND(C19="",D19=""),"",C19-D19)
... E207: =IF(AND(C207="",D207=""),"",C207-D207)
A208: TOTAL | C208: =IFERROR(SUM(C8:C207),0) -> 0 | D208: =IFERROR(SUM(D8:D207),0) -> 0 | E208: =IFERROR(SUM(E8:E207),0) -> 0
A210: 🔍 EXTRACTIONS AUTOMATIQUES (lues par le Dashboard)
A211: Créances clients | B211: comptes 342* | C211: =IFERROR(SUMIF(A8:A207,"342*",E8:E207),0) -> 0
A212: Dettes fournisseurs | B212: comptes 441* | C212: =IFERROR(-SUMIF(A8:A207,"441*",E8:E207),0) -> 0
A213: Chiffre d'affaires HT | B213: comptes 71* | C213: =IFERROR(-SUMIF(A8:A207,"71*",E8:E207),0) -> 0
A214: Achats HT | B214: comptes 61* | C214: =IFERROR(SUMIF(A8:A207,"61*",E8:E207),0) -> 0
A215: Stocks | B215: comptes 31* à 37* | C215: =IFERROR(SUMIF(A8:A207,"3*",E8:E207),0) -> 0
A217: ⚠ Extractions à 0 ? Les n° de compte ont des espaces (ex : « 342 000 »). Cliquez « Nettoyer » dans l'Accueil.

Sheet 2_Clients
A1: 2 · VOS CLIENTS — qui vous doit de l'argent, et depuis quand | L1: Export Dashboard → | M1: =IFERROR(SUM(I12:I111)/('0_Accueil'!$D$11*(1+'0_Accueil'!$D$12)/360),0) -> 0
A2: Tapez chaque facture client. Colonnes colorées = à remplir. Colonnes grises = calculées seules. Statut : IMPAYÉ (en retard) · EN COURS (pas encore due) · PAYÉ (réglée). | M2: =IFERROR(SUMPRODUCT(I12:I111,J12:J111)/SUM(I12:I111),0) -> 0
A3: Date du jour : | B3: ='0_Accueil'!$D$10 -> 46260 | C3: CA HT : | D3: ='0_Accueil'!$D$11 -> 0 | E3: TVA : | F3: ='0_Accueil'!$D$12 -> 0.2 | M3: =IFERROR(SUMIF(H12:H111,"PAYÉ",G12:G111)/SUM(G12:G111),0) -> 0
M4: =IFERROR(SUMPRODUCT(I12:I111,K12:K111)/SUMPRODUCT((K12:K111>0)*I12:I111),0) -> 0
A5: 📊 VOS INDICATEURS CLIENTS (calculés automatiquement) | M5: =IFERROR(SUMPRODUCT(I12:I111,K12:K111)/SUMPRODUCT(I12:I111,J12:J111),0) -> 0
A6: DSO GLOBAL | C6: DSO PONDÉRÉ | E6: TAUX RECOUVREMENT | G6: RETARD MOY. PONDÉRÉ | I6: IMPACT DES RETARDS | M6: =IFERROR(SUMPRODUCT((K12:K111>0)*I12:I111),0) -> 0
A7: ='2_Clients'!$M$1 -> 0 | C7: ='2_Clients'!$M$2 -> 0 | E7: ='2_Clients'!$M$3 -> 0 | G7: ='2_Clients'!$M$4 -> 0 | I7: ='2_Clients'!$M$5 -> 0 | M7: =IFERROR(SUM(I12:I111),0) -> 0
A8: jours | C8: jours | E8: % payé | G8: jours | I8: % encours | M8: =IFERROR(SUMPRODUCT((K12:K111>0)*1),0) -> 0
A11: Client | B11: N° Facture | C11: Date facture | D11: Date échéance | E11: Montant HT | F11: TVA % | G11: Mt TTC (auto) | H11: Statut | I11: Solde dû (auto) | J11: Jours écoulés | K11: Jours retard
G12: =IF(E12="","",IFERROR(E12*(1+F12),"")) | I12: =IF(OR(H12="",E12=""),0,IF(H12="PAYÉ",0,G12)) -> 0 | J12: =IF(OR(H12="PAYÉ",H12="",C12=""),0,MAX(0,$B$3-C12)) -> 0 | K12: =IF(OR(H12="PAYÉ",H12="",D12=""),0,MAX(0,$B$3-D12)) -> 0
G13: =IF(E13="","",IFERROR(E13*(1+F13),"")) | I13: =IF(OR(H13="",E13=""),0,IF(H13="PAYÉ",0,G13)) -> 0 | J13: =IF(OR(H13="PAYÉ",H13="",C13=""),0,MAX(0,$B$3-C13)) -> 0 | K13: =IF(OR(H13="PAYÉ",H13="",D13=""),0,MAX(0,$B$3-D13)) -> 0
G14: =IF(E14="","",IFERROR(E14*(1+F14),"")) | I14: =IF(OR(H14="",E14=""),0,IF(H14="PAYÉ",0,G14)) -> 0 | J14: =IF(OR(H14="PAYÉ",H14="",C14=""),0,MAX(0,$B$3-C14)) -> 0 | K14: =IF(OR(H14="PAYÉ",H14="",D14=""),0,MAX(0,$B$3-D14)) -> 0
G15: =IF(E15="","",IFERROR(E15*(1+F15),"")) | I15: =IF(OR(H15="",E15=""),0,IF(H15="PAYÉ",0,G15)) -> 0 | J15: =IF(OR(H15="PAYÉ",H15="",C15=""),0,MAX(0,$B$3-C15)) -> 0 | K15: =IF(OR(H15="PAYÉ",H15="",D15=""),0,MAX(0,$B$3-D15)) -> 0
G16: =IF(E16="","",IFERROR(E16*(1+F16),"")) | I16: =IF(OR(H16="",E16=""),0,IF(H16="PAYÉ",0,G16)) -> 0 | J16: =IF(OR(H16="PAYÉ",H16="",C16=""),0,MAX(0,$B$3-C16)) -> 0 | K16: =IF(OR(H16="PAYÉ",H16="",D16=""),0,MAX(0,$B$3-D16)) -> 0
G17: =IF(E17="","",IFERROR(E17*(1+F17),"")) | I17: =IF(OR(H17="",E17=""),0,IF(H17="PAYÉ",0,G17)) -> 0 | J17: =IF(OR(H17="PAYÉ",H17="",C17=""),0,MAX(0,$B$3-C17)) -> 0 | K17: =IF(OR(H17="PAYÉ",H17="",D17=""),0,MAX(0,$B$3-D17)) -> 0
G18: =IF(E18="","",IFERROR(E18*(1+F18),"")) | I18: =IF(OR(H18="",E18=""),0,IF(H18="PAYÉ",0,G18)) -> 0 | J18: =IF(OR(H18="PAYÉ",H18="",C18=""),0,MAX(0,$B$3-C18)) -> 0 | K18: =IF(OR(H18="PAYÉ",H18="",D18=""),0,MAX(0,$B$3-D18)) -> 0
G19: =IF(E19="","",IFERROR(E19*(1+F19),"")) | I19: =IF(OR(H19="",E19=""),0,IF(H19="PAYÉ",0,G19)) -> 0 | J19: =IF(OR(H19="PAYÉ",H19="",C19=""),0,MAX(0,$B$3-C19)) -> 0 | K19: =IF(OR(H19="PAYÉ",H19="",D19=""),0,MAX(0,$B$3-D19)) -> 0
G20: =IF(E20="","",IFERROR(E20*(1+F20),"")) | I20: =IF(OR(H20="",E20=""),0,IF(H20="PAYÉ",0,G20)) -> 0 | J20: =IF(OR(H20="PAYÉ",H20="",C20=""),0,MAX(0,$B$3-C20)) -> 0 | K20: =IF(OR(H20="PAYÉ",H20="",D20=""),0,MAX(0,$B$3-D20)) -> 0
G21: =IF(E21="","",IFERROR(E21*(1+F21),"")) | I21: =IF(OR(H21="",E21=""),0,IF(H21="PAYÉ",0,G21)) -> 0 | J21: =IF(OR(H21="PAYÉ",H21="",C21=""),0,MAX(0,$B$3-C21)) -> 0 | K21: =IF(OR(H21="PAYÉ",H21="",D21=""),0,MAX(0,$B$3-D21)) -> 0
G22: =IF(E22="","",IFERROR(E22*(1+F22),"")) | I22: =IF(OR(H22="",E22=""),0,IF(H22="PAYÉ",0,G22)) -> 0 | J22: =IF(OR(H22="PAYÉ",H22="",C22=""),0,MAX(0,$B$3-C22)) -> 0 | K22: =IF(OR(H22="PAYÉ",H22="",D22=""),0,MAX(0,$B$3-D22)) -> 0
G23: =IF(E23="","",IFERROR(E23*(1+F23),"")) | I23: =IF(OR(H23="",E23=""),0,IF(H23="PAYÉ",0,G23)) -> 0 | J23: =IF(OR(H23="PAYÉ",H23="",C23=""),0,MAX(0,$B$3-C23)) -> 0 | K23: =IF(OR(H23="PAYÉ",H23="",D23=""),0,MAX(0,$B$3-D23)) -> 0
... G111: =IF(E111="","",IFERROR(E111*(1+F111),"")) | I111: =IF(OR(H111="",E111=""),0,IF(H111="PAYÉ",0,G111)) -> 0 | J111: =IF(OR(H111="PAYÉ",H111="",C111=""),0,MAX(0,$B$3-C111)) -> 0 | K111: =IF(OR(H111="PAYÉ",H111="",D111=""),0,MAX(0,$B$3-D111)) -> 0
A112: TOTAL | E112: =IFERROR(SUM(E12:E111),0) -> 0 | G112: =IFERROR(SUM(G12:G111),0) -> 0 | I112: =IFERROR(SUM(I12:I111),0) -> 0

Sheet 3_Fournisseurs
A1: 3 · VOS FOURNISSEURS — qui vous devez payer, et sous quel délai | L1: Export → | M1: =IFERROR(SUM(J12:J71)/('1_Balance_GL'!$C$214*(1+'0_Accueil'!$D$12)/360),0) -> 0
A2: Tapez chaque facture fournisseur. « Délai contractuel » = le nombre de jours convenu pour payer (ex : 60). La date d'échéance se calcule seule. Statut : DÛ (à payer) · EN COURS · PAYÉ. | M2: =IFERROR(SUMPRODUCT(J12:J71,K12:K71)/SUM(J12:J71),0) -> 0
A3: Date du jour : | B3: ='0_Accueil'!$D$10 -> 46260 | C3: Achats HT (Balance) : | D3: ='1_Balance_GL'!$C$214 -> 0 | F3: TVA : | G3: ='0_Accueil'!$D$12 -> 0.2 | M3: =IFERROR(SUMPRODUCT(J12:J71,D12:D71)/SUM(J12:J71),0) -> 0
M4: =IFERROR(M2-M3,0) -> 0
A5: 📊 VOS INDICATEURS FOURNISSEURS (calculés automatiquement) | M5: =IFERROR(SUM(J12:J71),0) -> 0
A6: DPO GLOBAL (simplifié) | D6: DPO PONDÉRÉ | G6: DÉLAI CONTRACTUEL MOY. | I6: ÉCART RÉEL vs CONTRAT
A7: ='3_Fournisseurs'!$M$1 -> 0 | D7: ='3_Fournisseurs'!$M$2 -> 0 | G7: ='3_Fournisseurs'!$M$3 -> 0 | I7: ='3_Fournisseurs'!$M$4 -> 0
A8: jours | D8: jours | G8: jours | I8: jours
A11: Fournisseur | B11: N° Facture | C11: Date facture | D11: Délai (j) | E11: Échéance (auto) | F11: Montant HT | G11: TVA % | H11: Mt TTC (auto) | I11: Statut | J11: Solde (auto) | K11: Jours écoulés
E12: =IF(C12="","",C12+D12) | H12: =IF(F12="","",IFERROR(F12*(1+G12),"")) | J12: =IF(OR(I12="",F12=""),0,IF(I12="PAYÉ",0,H12)) -> 0 | K12: =IF(OR(I12="PAYÉ",I12="",C12=""),0,MAX(0,$B$3-C12)) -> 0
E13: =IF(C13="","",C13+D13) | H13: =IF(F13="","",IFERROR(F13*(1+G13),"")) | J13: =IF(OR(I13="",F13=""),0,IF(I13="PAYÉ",0,H13)) -> 0 | K13: =IF(OR(I13="PAYÉ",I13="",C13=""),0,MAX(0,$B$3-C13)) -> 0
E14: =IF(C14="","",C14+D14) | H14: =IF(F14="","",IFERROR(F14*(1+G14),"")) | J14: =IF(OR(I14="",F14=""),0,IF(I14="PAYÉ",0,H14)) -> 0 | K14: =IF(OR(I14="PAYÉ",I14="",C14=""),0,MAX(0,$B$3-C14)) -> 0
E15: =IF(C15="","",C15+D15) | H15: =IF(F15="","",IFERROR(F15*(1+G15),"")) | J15: =IF(OR(I15="",F15=""),0,IF(I15="PAYÉ",0,H15)) -> 0 | K15: =IF(OR(I15="PAYÉ",I15="",C15=""),0,MAX(0,$B$3-C15)) -> 0
E16: =IF(C16="","",C16+D16) | H16: =IF(F16="","",IFERROR(F16*(1+G16),"")) | J16: =IF(OR(I16="",F16=""),0,IF(I16="PAYÉ",0,H16)) -> 0 | K16: =IF(OR(I16="PAYÉ",I16="",C16=""),0,MAX(0,$B$3-C16)) -> 0
E17: =IF(C17="","",C17+D17) | H17: =IF(F17="","",IFERROR(F17*(1+G17),"")) | J17: =IF(OR(I17="",F17=""),0,IF(I17="PAYÉ",0,H17)) -> 0 | K17: =IF(OR(I17="PAYÉ",I17="",C17=""),0,MAX(0,$B$3-C17)) -> 0
E18: =IF(C18="","",C18+D18) | H18: =IF(F18="","",IFERROR(F18*(1+G18),"")) | J18: =IF(OR(I18="",F18=""),0,IF(I18="PAYÉ",0,H18)) -> 0 | K18: =IF(OR(I18="PAYÉ",I18="",C18=""),0,MAX(0,$B$3-C18)) -> 0
E19: =IF(C19="","",C19+D19) | H19: =IF(F19="","",IFERROR(F19*(1+G19),"")) | J19: =IF(OR(I19="",F19=""),0,IF(I19="PAYÉ",0,H19)) -> 0 | K19: =IF(OR(I19="PAYÉ",I19="",C19=""),0,MAX(0,$B$3-C19)) -> 0
E20: =IF(C20="","",C20+D20) | H20: =IF(F20="","",IFERROR(F20*(1+G20),"")) | J20: =IF(OR(I20="",F20=""),0,IF(I20="PAYÉ",0,H20)) -> 0 | K20: =IF(OR(I20="PAYÉ",I20="",C20=""),0,MAX(0,$B$3-C20)) -> 0
E21: =IF(C21="","",C21+D21) | H21: =IF(F21="","",IFERROR(F21*(1+G21),"")) | J21: =IF(OR(I21="",F21=""),0,IF(I21="PAYÉ",0,H21)) -> 0 | K21: =IF(OR(I21="PAYÉ",I21="",C21=""),0,MAX(0,$B$3-C21)) -> 0
E22: =IF(C22="","",C22+D22) | H22: =IF(F22="","",IFERROR(F22*(1+G22),"")) | J22: =IF(OR(I22="",F22=""),0,IF(I22="PAYÉ",0,H22)) -> 0 | K22: =IF(OR(I22="PAYÉ",I22="",C22=""),0,MAX(0,$B$3-C22)) -> 0
E23: =IF(C23="","",C23+D23) | H23: =IF(F23="","",IFERROR(F23*(1+G23),"")) | J23: =IF(OR(I23="",F23=""),0,IF(I23="PAYÉ",0,H23)) -> 0 | K23: =IF(OR(I23="PAYÉ",I23="",C23=""),0,MAX(0,$B$3-C23)) -> 0
... E71: =IF(C71="","",C71+D71) | H71: =IF(F71="","",IFERROR(F71*(1+G71),"")) | J71: =IF(OR(I71="",F71=""),0,IF(I71="PAYÉ",0,H71)) -> 0 | K71: =IF(OR(I71="PAYÉ",I71="",C71=""),0,MAX(0,$B$3-C71)) -> 0
A72: TOTAL | F72: =IFERROR(SUM(F12:F71),0) -> 0 | H72: =IFERROR(SUM(H12:H71),0) -> 0 | J72: =IFERROR(SUM(J12:J71),0) -> 0

Sheet 4_Stocks
A1: 4 · VOS STOCKS — combien de temps vos produits dorment avant d'être vendus
A2: Une ligne par type de stock. Remplissez : stock de début, stock de fin, et le coût annuel des sorties (ce qui est sorti du stock dans l'année). Le DIO = nombre de jours de stock. La Rotation = combien de fois le stock tourne dans l'année. Tout en bas : le total de TOUS vos stocks. | H2: Export →
H3: =IFERROR(D11/E11*360,0) -> 0
A4: Type de stock | B4: Stock début (DH) | C4: Stock fin (DH) | D4: Stock moyen (auto) | E4: Coût annuel sorties (DH) | F4: DIO (auto) | G4: Rotation (auto) | H4: =IFERROR(E11/D11,0) -> 0
A5: Matières premières | D5: =IF(AND(B5="",C5=""),"",(B5+C5)/2) | F5: =IF(OR(D5="",E5=""),"",IFERROR(D5/E5*360,"")) | G5: =IF(OR(D5="",E5=""),"",IFERROR(E5/D5,"")) | H5: =IFERROR(D11,0) -> 0
A6: En-cours de production | D6: =IF(AND(B6="",C6=""),"",(B6+C6)/2) | F6: =IF(OR(D6="",E6=""),"",IFERROR(D6/E6*360,"")) | G6: =IF(OR(D6="",E6=""),"",IFERROR(E6/D6,""))
A7: Produits finis | D7: =IF(AND(B7="",C7=""),"",(B7+C7)/2) | F7: =IF(OR(D7="",E7=""),"",IFERROR(D7/E7*360,"")) | G7: =IF(OR(D7="",E7=""),"",IFERROR(E7/D7,""))
A8: Marchandises | D8: =IF(AND(B8="",C8=""),"",(B8+C8)/2) | F8: =IF(OR(D8="",E8=""),"",IFERROR(D8/E8*360,"")) | G8: =IF(OR(D8="",E8=""),"",IFERROR(E8/D8,""))
D9: =IF(AND(B9="",C9=""),"",(B9+C9)/2) | F9: =IF(OR(D9="",E9=""),"",IFERROR(D9/E9*360,"")) | G9: =IF(OR(D9="",E9=""),"",IFERROR(E9/D9,""))
D10: =IF(AND(B10="",C10=""),"",(B10+C10)/2) | F10: =IF(OR(D10="",E10=""),"",IFERROR(D10/E10*360,"")) | G10: =IF(OR(D10="",E10=""),"",IFERROR(E10/D10,""))
A11: TOTAL / GLOBAL | B11: =IFERROR(SUM(B5:B10),0) -> 0 | C11: =IFERROR(SUM(C5:C10),0) -> 0 | D11: =IFERROR(SUM(D5:D10),0) -> 0 | E11: =IFERROR(SUM(E5:E10),0) -> 0 | F11: =IFERROR(D11/E11*360,0) -> 0 | G11: =IFERROR(E11/D11,0) -> 0
A13: 📦 RÉSULTAT — combien de jours vos produits dorment en stock
A14: DIO GLOBAL | C14: =IFERROR(D11/E11*360,0) -> 0 | E14: jours · c'est le temps moyen entre l'entrée en stock et la vente. Plus c'est petit, moins d'argent dort.

Sheet 5_Dashboard
B1: TABLEAU DE BORD — VOTRE TRÉSORERIE EN CLAIR
B2: ='0_Accueil'!$D$8 -> dss | G2: ='0_Accueil'!$D$10 -> 46260
B4: Ce tableau répond à une seule question : combien de temps VOTRE argent reste coincé avant de revenir dans votre poche ? Plus les délais sont courts, mieux vous respirez.
B6: ① D'OÙ VIENNENT VOS CHIFFRES ? (choisissez ci-dessous)
B7: Ma source : | C7: ÉCHÉANCIER | D7: =" → Vous regardez actuellement : "&$C$7 -> → Vous regardez actuellement : ÉCHÉANCIER
B8: 📋 ÉCHÉANCIER (facture par facture) | F8: 📊 BALANCE GÉNÉRALE (les totaux)
B9: Vous avez tapé vos factures une par une (onglets Clients & Fournisseurs). → Calcul TRÈS précis, comme peser chaque fruit du panier. Choisissez ceci si les onglets Clients et Fournisseurs sont remplis. | F9: Vous avez juste collé les totaux de votre logiciel (onglet Balance). → Calcul rapide, comme peser tout le panier d'un coup. Choisissez ceci si vous avez seulement la balance comptable.
B10: 🤔 Pas sûr ? Si les onglets Clients & Fournisseurs sont remplis → ÉCHÉANCIER. Sinon → BALANCE GÉNÉRALE.
B12: ② VOS 3 CHIFFRES CLÉS (expliqués simplement)
B13: ⏱️ VOS CLIENTS VOUS PAIENT EN | E13: ⏳ VOUS PAYEZ VOS FOURNISSEURS EN | H13: 📦 VOS PRODUITS DORMENT EN STOCK
B14: =IFERROR(IF($C$7="BALANCE GÉNÉRALE",IFERROR('1_Balance_GL'!$C$211/('0_Accueil'!$D$11*(1+'0_Accueil'!$D$12)/360),0),'2_Clients'!$M$2),0) -> 0 | E14: =IFERROR(IF($C$7="BALANCE GÉNÉRALE",IFERROR('1_Balance_GL'!$C$212/('1_Balance_GL'!$C$214*(1+'0_Accueil'!$D$12)/360),0),'3_Fournisseurs'!$M$2),0) -> 0 | H14: =IFERROR('4_Stocks'!$H$3,0) -> 0
B15: ="Secteur "&'0_Accueil'!$D$9&" : "&ROUND(IFERROR(VLOOKUP('0_Accueil'!$D$9,$B$40:$F$44,2,FALSE),60),0)&" j" -> Secteur : 60 j | E15: ="Secteur "&'0_Accueil'!$D$9&" : "&ROUND(IFERROR(VLOOKUP('0_Accueil'!$D$9,$B$40:$F$44,3,FALSE),45),0)&" j" -> Secteur : 45 j | H15: ="Secteur "&'0_Accueil'!$D$9&" : "&ROUND(IFERROR(VLOOKUP('0_Accueil'!$D$9,$B$40:$F$44,4,FALSE),35),0)&" j" -> Secteur : 35 j
B16: Le temps que mettent vos clients à vous régler. Plus c'est court, plus vite l'argent rentre. | E16: Le temps que vous mettez à payer. Payer un peu tard = garder son cash plus longtemps (sans fâcher personne). | H16: Le temps que vos marchandises restent en stock avant d'être vendues. Plus c'est court, moins d'argent dort.
B17: =IF(IF($C$7="BALANCE GÉNÉRALE",IFERROR('1_Balance_GL'!$C$211/('0_Accueil'!$D$11*(1+'0_Accueil'!$D$12)/360),0),'2_Clients'!$M$2)<=IFERROR(VLOOKUP('0_Accueil'!$D$9,$B$40:$F$44,2,FALSE),60),"✔ EXCELLENT",IF(IF($C$7="BALANCE GÉNÉRALE",IFERROR('1_Balance_GL'!$C$211/('0_Accueil'!$D$11*(1+'0_Accueil'!$D$12)/360),0),'2_Clients'!$M$2)<=IFERROR(VLOOKUP('0_Accueil'!$D$9,$B$40:$F$44,2,FALSE),60)*1.15,"BON",IF(IF($C$7="BALANCE GÉNÉRALE",IFERROR('1_Balance_GL'!$C$211/('0_Accueil'!$D$11*(1+'0_Accueil'!$D$12)/360),0),'2_Clients'!$M$2)<=IFERROR(VLOOKUP('0_Accueil'!$D$9,$B$40:$F$44,2,FALSE),60)*1.4,"À SURVEILLER","⚠ ALERTE"))) -> ✔ EXCELLENT | E17: 🛈 garder le cash sans fâcher le fournisseur | H17: =IF('4_Stocks'!$H$3<=IFERROR(VLOOKUP('0_Accueil'!$D$9,$B$40:$F$44,4,FALSE),35),"✔ EXCELLENT",IF('4_Stocks'!$H$3<=IFERROR(VLOOKUP('0_Accueil'!$D$9,$B$40:$F$44,4,FALSE),35)*1.15,"BON",IF('4_Stocks'!$H$3<=IFERROR(VLOOKUP('0_Accueil'!$D$9,$B$40:$F$44,4,FALSE),35)*1.4,"À SURVEILLER","⚠ ALERTE"))) -> ✔ EXCELLENT
B19: ③ LE VERDICT : DE COMBIEN DE CASH AVEZ-VOUS BESOIN ?
B20: 💰 VOTRE BESOIN EN CASH (BFR) | F20: 🔄 VOTRE CYCLE DE CASH (CCC)
B21: =IFERROR(IFERROR('1_Balance_GL'!$C$211/(1+'0_Accueil'!$D$12),0)+IFERROR('4_Stocks'!$H$5,0)-IFERROR('1_Balance_GL'!$C$212/(1+'0_Accueil'!$D$12),0),0) -> 0 | F21: =IFERROR(IF($C$7="BALANCE GÉNÉRALE",IFERROR('1_Balance_GL'!$C$211/('0_Accueil'!$D$11*(1+'0_Accueil'!$D$12)/360),0),'2_Clients'!$M$2)+'4_Stocks'!$H$3-IF($C$7="BALANCE GÉNÉRALE",IFERROR('1_Balance_GL'!$C$212/('1_Balance_GL'!$C$214*(1+'0_Accueil'!$D$12)/360),0),'3_Fournisseurs'!$M$2),0) -> 0
B22: C'est l'argent que votre activité « mange » en permanence pour tourner. BFR = ce que vos clients vous doivent + vos stocks − ce que vous devez aux fournisseurs. Positif = vous devez avancer cette somme. Négatif = votre activité s'autofinance. | F22: Entre le moment où vous payez vos fournisseurs et celui où vos clients vous paient, il s'écoule ce nombre de jours. Pendant ce temps, c'est VOTRE argent qui finance tout. CCC = DSO + DIO − DPO. Plus il est petit (ou négatif), mieux c'est.
B23: =IF(IFERROR(IF($C$7="BALANCE GÉNÉRALE",IFERROR('1_Balance_GL'!$C$211/('0_Accueil'!$D$11*(1+'0_Accueil'!$D$12)/360),0),'2_Clients'!$M$2)+'4_Stocks'!$H$3-IF($C$7="BALANCE GÉNÉRALE",IFERROR('1_Balance_GL'!$C$212/('1_Balance_GL'!$C$214*(1+'0_Accueil'!$D$12)/360),0),'3_Fournisseurs'!$M$2),0)<=30,"✔ Cycle court : votre trésorerie respire bien.",IF(IFERROR(IF($C$7="BALANCE GÉNÉRALE",IFERROR('1_Balance_GL'!$C$211/('0_Accueil'!$D$11*(1+'0_Accueil'!$D$12)/360),0),'2_Clients'!$M$2)+'4_Stocks'!$H$3-IF($C$7="BALANCE GÉNÉRALE",IFERROR('1_Balance_GL'!$C$212/('1_Balance_GL'!$C$214*(1+'0_Accueil'!$D$12)/360),0),'3_Fournisseurs'!$M$2),0)<=60,"Cycle correct : surveillez vos délais clients.",IF(IFERROR(IF($C$7="BALANCE GÉNÉRALE",IFERROR('1_Balance_GL'!$C$211/('0_Accueil'!$D$11*(1+'0_Accueil'!$D$12)/360),0),'2_Clients'!$M$2)+'4_Stocks'!$H$3-IF($C$7="BALANCE GÉNÉRALE",IFERROR('1_Balance_GL'!$C$212/('1_Balance_GL'!$C$214*(1+'0_Accueil'!$D$12)/360),0),'3_Fournisseurs'!$M$2),0)<=90,"⚠ Cycle long : votre cash est immobilisé, agissez sur le DSO ou le DIO.","⚠ Cycle très long : priorité absolue à réduire créances et stocks."))) -> ✔ Cycle court : votre trésorerie respire bien.
B25: ④ LES MOYENNES DE VOTRE SECTEUR AU MAROC (pour vous comparer)
B26: Comparez vos chiffres ci-dessus à la moyenne de votre secteur. Le vôtre est en surbrillance si vous l'avez saisi dans l'Accueil.
B27: Secteur | C27: DSO moyen | E27: DPO moyen | F27: DIO moyen | H27: BFR / CA
B28: Distribution | C28: 45 | E28: 30 | F28: 30 | H28: 8–12 %
B29: Industrie | C29: 60 | E29: 45 | F29: 45 | H29: 15–20 %
B30: BTP | C30: 90 | E30: 60 | F30: 20 | H30: 20–30 %
B31: Services | C31: 30 | E31: 15 | F31: 5 | H31: 5–10 %
B32: Agroalimentaire | C32: 35 | E32: 25 | F32: 20 | H32: 6–12 %
B34: ⑤ VOS DONNÉES SONT-ELLES COHÉRENTES ?
B35: Écart DSO (2 méthodes) : | C35: =IFERROR(ABS('2_Clients'!$M$1-'2_Clients'!$M$2),0) -> 0 | D35: ← moins de 5 j : parfait · 5 à 15 j : à vérifier · plus de 15 j : données incomplètes
B36: 🔒 Onglets protégés. Mot de passe si besoin : BYE2026
B39: Table de référence (ne pas modifier) :
B40: Distribution | C40: 45 | D40: 30 | E40: 30 | F40: 8–12 %
B41: Industrie | C41: 60 | D41: 45 | E41: 45 | F41: 15–20 %
B42: BTP | C42: 90 | D42: 60 | E42: 20 | F42: 20–30 %
B43: Services | C43: 30 | D43: 15 | E43: 5 | F43: 5–10 %
B44: Agroalimentaire | C44: 35 | D44: 25 | E44: 20 | F44: 6–12 %

Sheet Lecture
B1: 📖 MODE D'EMPLOI — DashboardBFR v5
B3: ▸ EN 30 SECONDES
B4: À quoi ça sert | C4: À savoir combien de temps votre argent reste bloqué (clients qui tardent, stock qui dort) et combien de cash votre activité réclame en permanence.
B5: Par où commencer | C5: Onglet Accueil → remplissez les cases colorées. Puis SOIT collez votre balance (onglet Balance), SOIT tapez vos factures (Clients/Fournisseurs). Puis lisez le Dashboard.
B7: ▸ ÉCHÉANCIER OU BALANCE ?
B8: Échéancier (précis) | C8: Vous tapez vos factures une par une. Les DSO/DPO sont PONDÉRÉS : une grosse facture pèse plus qu'une petite. C'est la vérité du terrain.
B9: Balance (rapide) | C9: Vous collez les totaux de votre logiciel. Les DSO/DPO sont GLOBAUX (une moyenne). Rapide, suffisant pour une première photo.
B10: Le choix | C10: Dans le Dashboard, case « Ma source ». Aucun calcul ne change dans le fond : seule la source des chiffres change.
B12: ▸ CE QUE CHAQUE CHIFFRE VEUT DIRE
B13: DSO | C13: Jours que mettent vos CLIENTS à vous payer. Bas = bon.
B14: DPO | C14: Jours que VOUS mettez à payer vos fournisseurs. Un DPO proche du délai contractuel = sain.
B15: DIO | C15: Jours pendant lesquels vos PRODUITS restent en stock. Bas = bon.
B16: Taux de recouvrement | C16: Part de vos factures déjà encaissées (payées) sur le total facturé.
B17: Retard moyen pondéré | C17: Combien de jours de retard, en moyenne (pondérée par montant), sur vos factures échues.
B18: Indice d'impact des retards | C18: Part de votre encours-jours qui vient des retards. Élevé = vos retardataires plombent votre DSO.
B19: Délai contractuel moyen | C19: La moyenne (pondérée) des délais que vous avez négociés avec vos fournisseurs.
B20: Écart réel vs contrat | C20: DPO réel − délai négocié. Positif = vous dépassez (risque fournisseur). Négatif = vous payez trop vite (cash perdu).
B21: BFR | C21: Créances HT + Stocks − Dettes HT. L'argent que l'activité immobilise.
B22: CCC | C22: DSO + DIO − DPO. Le cycle complet avant que le cash revienne.
B24: ▸ SI ÇA COINCE
B25: Extractions à 0 | C25: Les n° de compte ont des espaces (« 342 000 »). Bouton « Nettoyer » dans l'Accueil.
B26: Chiffres bizarres | C26: Vérifiez le CA et la TVA de l'Accueil (TVA = 0.20, pas 20).
B27: Je veux tout modifier | C27: Révision → Ôter la protection. Mot de passe : BYE2026

Sheet Cash Management
A1: CASH MANAGEMENT — PILOTAGE DE LA TRÉSORERIE OPÉRATIONNELLE
A3: ="Société : "&IF('0_Accueil'!$D$8="","Non renseignée",'0_Accueil'!$D$8) -> Société : dss | G3: ="Date d'arrêté : "&TEXT('0_Accueil'!$D$10,"dd/mm/yyyy") -> #VALUE! | K3: ="Secteur : "&IF('0_Accueil'!$D$9="","Non renseigné",'0_Accueil'!$D$9) -> Secteur : Non renseigné
A4: Lecture opérationnelle clients–fournisseurs–stocks. Les soldes bancaires, la paie, la fiscalité, la dette et le CAPEX ne sont pas inclus dans cette version.
A5: ① LES 10 KPI DE TRÉSORERIE — VUE DG / DAF
A6: CASH NET OPÉRATIONNEL À 30 JOURS | D6: BESOIN MAXIMUM — 13 SEMAINES | G6: COUVERTURE DES DÉCAISSEMENTS — 30 J | J6: BFR IMMOBILISÉ | M6: CYCLE DE CONVERSION DU CASH
A7: =IFERROR(SUMIFS('2_Clients'!$I$12:$I$111,'2_Clients'!$D$12:$D$111,">0",'2_Clients'!$D$12:$D$111,"<="&'0_Accueil'!$D$10+30,'2_Clients'!$I$12:$I$111,">0")-SUMIFS('3_Fournisseurs'!$J$12:$J$71,'3_Fournisseurs'!$E$12:$E$71,">0",'3_Fournisseurs'!$E$12:$E$71,"<="&'0_Accueil'!$D$10+30,'3_Fournisseurs'!$J$12:$J$71,">0"),0) -> 0 | D7: =ABS(MIN(0,$G$21:$G$33)) -> 0 | G7: =IFERROR(SUMIFS('2_Clients'!$I$12:$I$111,'2_Clients'!$D$12:$D$111,">0",'2_Clients'!$D$12:$D$111,"<="&'0_Accueil'!$D$10+30,'2_Clients'!$I$12:$I$111,">0")/SUMIFS('3_Fournisseurs'!$J$12:$J$71,'3_Fournisseurs'!$E$12:$E$71,">0",'3_Fournisseurs'!$E$12:$E$71,"<="&'0_Accueil'!$D$10+30,'3_Fournisseurs'!$J$12:$J$71,">0"),0) -> 0 | J7: ='5_Dashboard'!$B$21 -> 0 | M7: ='5_Dashboard'!$F$21 -> 0
A9: Encaissements exigibles − paiements fournisseurs exigibles. | D9: Point de tension maximal du calendrier opérationnel cumulé. | G9: Au-dessus de 1,00× : les encaissements couvrent les sorties. | J9: Besoin permanent financé par l'entreprise. | M9: DSO + DIO − DPO : durée de financement du cycle.
A11: CASH TOTAL LIBÉRABLE | D11: CASH CLIENTS À RISQUE | G11: VITESSE D'ENCAISSEMENT | J11: EXPOSITION OPÉRATIONNELLE NETTE | M11: CONCENTRATION — TOP 5 CLIENTS
A12: =$F$58 -> 0 | D12: =IFERROR(SUMIFS('2_Clients'!$I$12:$I$111,'2_Clients'!$K$12:$K$111,">0",'2_Clients'!$I$12:$I$111,">0"),0) -> 0 | G12: ='2_Clients'!$M$3 -> 0 | J12: ='2_Clients'!$M$7-'3_Fournisseurs'!$M$5 -> 0 | M12: =IFERROR(SUM(LARGE(SUMIF('2_Clients'!$A$12:$A$111,_xlfn.UNIQUE(_xlfn._xlws.FILTER('2_Clients'!$A$12:$A$111,'2_Clients'!$A$12:$A$111<>"")),'2_Clients'!$I$12:$I$111),_xludf.SEQUENCE(MIN(5,COUNTA(_xlfn.UNIQUE(_xlfn._xlws.FILTER('2_Clients'!$A$12:$A$111,'2_Clients'!$A$12:$A$111<>"")))))))/'2_Clients'!$M$7,0) -> 0
A14: Potentiel DSO + DIO + DPO par rapport aux cibles. | D14: Soldes clients échus à la date d'arrêté. | G14: Taux de recouvrement réel des factures. | J14: Encours clients − encours fournisseurs. | M14: Part de l'encours portée par les cinq principaux clients.
A16: DSO PONDÉRÉ | D16: DPO PONDÉRÉ | G16: DIO GLOBAL | J16: BFR EN JOURS DE CA | M16: ÉCART DPO / CONTRAT
A17: ='2_Clients'!$M$2 -> 0 | D17: ='3_Fournisseurs'!$M$2 -> 0 | G17: ='4_Stocks'!$H$3 -> 0 | J17: =IFERROR('5_Dashboard'!$B$21/'0_Accueil'!$D$11*360,0) -> 0 | M17: ='3_Fournisseurs'!$M$4 -> 0
A19: ② CALENDRIER DE CASH OPÉRATIONNEL — 13 SEMAINES
A20: Semaine | B20: Début | C20: Fin | D20: Encaissements | E20: Décaissements | F20: Cash net | G20: Cumul
A21: S1 | B21: ='0_Accueil'!$D$10 -> 46260 | C21: =B21+6 -> 46266 | D21: =IF($B21='0_Accueil'!$D$10,SUMIFS('2_Clients'!$I$12:$I$111,'2_Clients'!$D$12:$D$111,">0",'2_Clients'!$D$12:$D$111,"<="&$C21,'2_Clients'!$I$12:$I$111,">0"),SUMIFS('2_Clients'!$I$12:$I$111,'2_Clients'!$D$12:$D$111,">="&$B21,'2_Clients'!$D$12:$D$111,"<="&$C21,'2_Clients'!$I$12:$I$111,">0")) -> 0 | E21: =IF($B21='0_Accueil'!$D$10,SUMIFS('3_Fournisseurs'!$J$12:$J$71,'3_Fournisseurs'!$E$12:$E$71,">0",'3_Fournisseurs'!$E$12:$E$71,"<="&$C21,'3_Fournisseurs'!$J$12:$J$71,">0"),SUMIFS('3_Fournisseurs'!$J$12:$J$71,'3_Fournisseurs'!$E$12:$E$71,">="&$B21,'3_Fournisseurs'!$E$12:$E$71,"<="&$C21,'3_Fournisseurs'!$J$12:$J$71,">0")) -> 0 | F21: =D21-E21 -> 0 | G21: =F21 -> 0
A22: S2 | B22: =C21+1 -> 46267 | C22: =B22+6 -> 46273 | D22: =IF($B22='0_Accueil'!$D$10,SUMIFS('2_Clients'!$I$12:$I$111,'2_Clients'!$D$12:$D$111,">0",'2_Clients'!$D$12:$D$111,"<="&$C22,'2_Clients'!$I$12:$I$111,">0"),SUMIFS('2_Clients'!$I$12:$I$111,'2_Clients'!$D$12:$D$111,">="&$B22,'2_Clients'!$D$12:$D$111,"<="&$C22,'2_Clients'!$I$12:$I$111,">0")) -> 0 | E22: =IF($B22='0_Accueil'!$D$10,SUMIFS('3_Fournisseurs'!$J$12:$J$71,'3_Fournisseurs'!$E$12:$E$71,">0",'3_Fournisseurs'!$E$12:$E$71,"<="&$C22,'3_Fournisseurs'!$J$12:$J$71,">0"),SUMIFS('3_Fournisseurs'!$J$12:$J$71,'3_Fournisseurs'!$E$12:$E$71,">="&$B22,'3_Fournisseurs'!$E$12:$E$71,"<="&$C22,'3_Fournisseurs'!$J$12:$J$71,">0")) -> 0 | F22: =D22-E22 -> 0 | G22: =G21+F22 -> 0
A23: S3 | B23: =C22+1 -> 46274 | C23: =B23+6 -> 46280 | D23: =IF($B23='0_Accueil'!$D$10,SUMIFS('2_Clients'!$I$12:$I$111,'2_Clients'!$D$12:$D$111,">0",'2_Clients'!$D$12:$D$111,"<="&$C23,'2_Clients'!$I$12:$I$111,">0"),SUMIFS('2_Clients'!$I$12:$I$111,'2_Clients'!$D$12:$D$111,">="&$B23,'2_Clients'!$D$12:$D$111,"<="&$C23,'2_Clients'!$I$12:$I$111,">0")) -> 0 | E23: =IF($B23='0_Accueil'!$D$10,SUMIFS('3_Fournisseurs'!$J$12:$J$71,'3_Fournisseurs'!$E$12:$E$71,">0",'3_Fournisseurs'!$E$12:$E$71,"<="&$C23,'3_Fournisseurs'!$J$12:$J$71,">0"),SUMIFS('3_Fournisseurs'!$J$12:$J$71,'3_Fournisseurs'!$E$12:$E$71,">="&$B23,'3_Fournisseurs'!$E$12:$E$71,"<="&$C23,'3_Fournisseurs'!$J$12:$J$71,">0")) -> 0 | F23: =D23-E23 -> 0 | G23: =G22+F23 -> 0
A24: S4 | B24: =C23+1 -> 46281 | C24: =B24+6 -> 46287 | D24: =IF($B24='0_Accueil'!$D$10,SUMIFS('2_Clients'!$I$12:$I$111,'2_Clients'!$D$12:$D$111,">0",'2_Clients'!$D$12:$D$111,"<="&$C24,'2_Clients'!$I$12:$I$111,">0"),SUMIFS('2_Clients'!$I$12:$I$111,'2_Clients'!$D$12:$D$111,">="&$B24,'2_Clients'!$D$12:$D$111,"<="&$C24,'2_Clients'!$I$12:$I$111,">0")) -> 0 | E24: =IF($B24='0_Accueil'!$D$10,SUMIFS('3_Fournisseurs'!$J$12:$J$71,'3_Fournisseurs'!$E$12:$E$71,">0",'3_Fournisseurs'!$E$12:$E$71,"<="&$C24,'3_Fournisseurs'!$J$12:$J$71,">0"),SUMIFS('3_Fournisseurs'!$J$12:$J$71,'3_Fournisseurs'!$E$12:$E$71,">="&$B24,'3_Fournisseurs'!$E$12:$E$71,"<="&$C24,'3_Fournisseurs'!$J$12:$J$71,">0")) -> 0 | F24: =D24-E24 -> 0 | G24: =G23+F24 -> 0
A25: S5 | B25: =C24+1 -> 46288 | C25: =B25+6 -> 46294 | D25: =IF($B25='0_Accueil'!$D$10,SUMIFS('2_Clients'!$I$12:$I$111,'2_Clients'!$D$12:$D$111,">0",'2_Clients'!$D$12:$D$111,"<="&$C25,'2_Clients'!$I$12:$I$111,">0"),SUMIFS('2_Clients'!$I$12:$I$111,'2_Clients'!$D$12:$D$111,">="&$B25,'2_Clients'!$D$12:$D$111,"<="&$C25,'2_Clients'!$I$12:$I$111,">0")) -> 0 | E25: =IF($B25='0_Accueil'!$D$10,SUMIFS('3_Fournisseurs'!$J$12:$J$71,'3_Fournisseurs'!$E$12:$E$71,">0",'3_Fournisseurs'!$E$12:$E$71,"<="&$C25,'3_Fournisseurs'!$J$12:$J$71,">0"),SUMIFS('3_Fournisseurs'!$J$12:$J$71,'3_Fournisseurs'!$E$12:$E$71,">="&$B25,'3_Fournisseurs'!$E$12:$E$71,"<="&$C25,'3_Fournisseurs'!$J$12:$J$71,">0")) -> 0 | F25: =D25-E25 -> 0 | G25: =G24+F25 -> 0
A26: S6 | B26: =C25+1 -> 46295 | C26: =B26+6 -> 46301 | D26: =IF($B26='0_Accueil'!$D$10,SUMIFS('2_Clients'!$I$12:$I$111,'2_Clients'!$D$12:$D$111,">0",'2_Clients'!$D$12:$D$111,"<="&$C26,'2_Clients'!$I$12:$I$111,">0"),SUMIFS('2_Clients'!$I$12:$I$111,'2_Clients'!$D$12:$D$111,">="&$B26,'2_Clients'!$D$12:$D$111,"<="&$C26,'2_Clients'!$I$12:$I$111,">0")) -> 0 | E26: =IF($B26='0_Accueil'!$D$10,SUMIFS('3_Fournisseurs'!$J$12:$J$71,'3_Fournisseurs'!$E$12:$E$71,">0",'3_Fournisseurs'!$E$12:$E$71,"<="&$C26,'3_Fournisseurs'!$J$12:$J$71,">0"),SUMIFS('3_Fournisseurs'!$J$12:$J$71,'3_Fournisseurs'!$E$12:$E$71,">="&$B26,'3_Fournisseurs'!$E$12:$E$71,"<="&$C26,'3_Fournisseurs'!$J$12:$J$71,">0")) -> 0 | F26: =D26-E26 -> 0 | G26: =G25+F26 -> 0
A27: S7 | B27: =C26+1 -> 46302 | C27: =B27+6 -> 46308 | D27: =IF($B27='0_Accueil'!$D$10,SUMIFS('2_Clients'!$I$12:$I$111,'2_Clients'!$D$12:$D$111,">0",'2_Clients'!$D$12:$D$111,"<="&$C27,'2_Clients'!$I$12:$I$111,">0"),SUMIFS('2_Clients'!$I$12:$I$111,'2_Clients'!$D$12:$D$111,">="&$B27,'2_Clients'!$D$12:$D$111,"<="&$C27,'2_Clients'!$I$12:$I$111,">0")) -> 0 | E27: =IF($B27='0_Accueil'!$D$10,SUMIFS('3_Fournisseurs'!$J$12:$J$71,'3_Fournisseurs'!$E$12:$E$71,">0",'3_Fournisseurs'!$E$12:$E$71,"<="&$C27,'3_Fournisseurs'!$J$12:$J$71,">0"),SUMIFS('3_Fournisseurs'!$J$12:$J$71,'3_Fournisseurs'!$E$12:$E$71,">="&$B27,'3_Fournisseurs'!$E$12:$E$71,"<="&$C27,'3_Fournisseurs'!$J$12:$J$71,">0")) -> 0 | F27: =D27-E27 -> 0 | G27: =G26+F27 -> 0
A28: S8 | B28: =C27+1 -> 46309 | C28: =B28+6 -> 46315 | D28: =IF($B28='0_Accueil'!$D$10,SUMIFS('2_Clients'!$I$12:$I$111,'2_Clients'!$D$12:$D$111,">0",'2_Clients'!$D$12:$D$111,"<="&$C28,'2_Clients'!$I$12:$I$111,">0"),SUMIFS('2_Clients'!$I$12:$I$111,'2_Clients'!$D$12:$D$111,">="&$B28,'2_Clients'!$D$12:$D$111,"<="&$C28,'2_Clients'!$I$12:$I$111,">0")) -> 0 | E28: =IF($B28='0_Accueil'!$D$10,SUMIFS('3_Fournisseurs'!$J$12:$J$71,'3_Fournisseurs'!$E$12:$E$71,">0",'3_Fournisseurs'!$E$12:$E$71,"<="&$C28,'3_Fournisseurs'!$J$12:$J$71,">0"),SUMIFS('3_Fournisseurs'!$J$12:$J$71,'3_Fournisseurs'!$E$12:$E$71,">="&$B28,'3_Fournisseurs'!$E$12:$E$71,"<="&$C28,'3_Fournisseurs'!$J$12:$J$71,">0")) -> 0 | F28: =D28-E28 -> 0 | G28: =G27+F28 -> 0
A29: S9 | B29: =C28+1 -> 46316 | C29: =B29+6 -> 46322 | D29: =IF($B29='0_Accueil'!$D$10,SUMIFS('2_Clients'!$I$12:$I$111,'2_Clients'!$D$12:$D$111,">0",'2_Clients'!$D$12:$D$111,"<="&$C29,'2_Clients'!$I$12:$I$111,">0"),SUMIFS('2_Clients'!$I$12:$I$111,'2_Clients'!$D$12:$D$111,">="&$B29,'2_Clients'!$D$12:$D$111,"<="&$C29,'2_Clients'!$I$12:$I$111,">0")) -> 0 | E29: =IF($B29='0_Accueil'!$D$10,SUMIFS('3_Fournisseurs'!$J$12:$J$71,'3_Fournisseurs'!$E$12:$E$71,">0",'3_Fournisseurs'!$E$12:$E$71,"<="&$C29,'3_Fournisseurs'!$J$12:$J$71,">0"),SUMIFS('3_Fournisseurs'!$J$12:$J$71,'3_Fournisseurs'!$E$12:$E$71,">="&$B29,'3_Fournisseurs'!$E$12:$E$71,"<="&$C29,'3_Fournisseurs'!$J$12:$J$71,">0")) -> 0 | F29: =D29-E29 -> 0 | G29: =G28+F29 -> 0
A30: S10 | B30: =C29+1 -> 46323 | C30: =B30+6 -> 46329 | D30: =IF($B30='0_Accueil'!$D$10,SUMIFS('2_Clients'!$I$12:$I$111,'2_Clients'!$D$12:$D$111,">0",'2_Clients'!$D$12:$D$111,"<="&$C30,'2_Clients'!$I$12:$I$111,">0"),SUMIFS('2_Clients'!$I$12:$I$111,'2_Clients'!$D$12:$D$111,">="&$B30,'2_Clients'!$D$12:$D$111,"<="&$C30,'2_Clients'!$I$12:$I$111,">0")) -> 0 | E30: =IF($B30='0_Accueil'!$D$10,SUMIFS('3_Fournisseurs'!$J$12:$J$71,'3_Fournisseurs'!$E$12:$E$71,">0",'3_Fournisseurs'!$E$12:$E$71,"<="&$C30,'3_Fournisseurs'!$J$12:$J$71,">0"),SUMIFS('3_Fournisseurs'!$J$12:$J$71,'3_Fournisseurs'!$E$12:$E$71,">="&$B30,'3_Fournisseurs'!$E$12:$E$71,"<="&$C30,'3_Fournisseurs'!$J$12:$J$71,">0")) -> 0 | F30: =D30-E30 -> 0 | G30: =G29+F30 -> 0
A31: S11 | B31: =C30+1 -> 46330 | C31: =B31+6 -> 46336 | D31: =IF($B31='0_Accueil'!$D$10,SUMIFS('2_Clients'!$I$12:$I$111,'2_Clients'!$D$12:$D$111,">0",'2_Clients'!$D$12:$D$111,"<="&$C31,'2_Clients'!$I$12:$I$111,">0"),SUMIFS('2_Clients'!$I$12:$I$111,'2_Clients'!$D$12:$D$111,">="&$B31,'2_Clients'!$D$12:$D$111,"<="&$C31,'2_Clients'!$I$12:$I$111,">0")) -> 0 | E31: =IF($B31='0_Accueil'!$D$10,SUMIFS('3_Fournisseurs'!$J$12:$J$71,'3_Fournisseurs'!$E$12:$E$71,">0",'3_Fournisseurs'!$E$12:$E$71,"<="&$C31,'3_Fournisseurs'!$J$12:$J$71,">0"),SUMIFS('3_Fournisseurs'!$J$12:$J$71,'3_Fournisseurs'!$E$12:$E$71,">="&$B31,'3_Fournisseurs'!$E$12:$E$71,"<="&$C31,'3_Fournisseurs'!$J$12:$J$71,">0")) -> 0 | F31: =D31-E31 -> 0 | G31: =G30+F31 -> 0
A32: S12 | B32: =C31+1 -> 46337 | C32: =B32+6 -> 46343 | D32: =IF($B32='0_Accueil'!$D$10,SUMIFS('2_Clients'!$I$12:$I$111,'2_Clients'!$D$12:$D$111,">0",'2_Clients'!$D$12:$D$111,"<="&$C32,'2_Clients'!$I$12:$I$111,">0"),SUMIFS('2_Clients'!$I$12:$I$111,'2_Clients'!$D$12:$D$111,">="&$B32,'2_Clients'!$D$12:$D$111,"<="&$C32,'2_Clients'!$I$12:$I$111,">0")) -> 0 | E32: =IF($B32='0_Accueil'!$D$10,SUMIFS('3_Fournisseurs'!$J$12:$J$71,'3_Fournisseurs'!$E$12:$E$71,">0",'3_Fournisseurs'!$E$12:$E$71,"<="&$C32,'3_Fournisseurs'!$J$12:$J$71,">0"),SUMIFS('3_Fournisseurs'!$J$12:$J$71,'3_Fournisseurs'!$E$12:$E$71,">="&$B32,'3_Fournisseurs'!$E$12:$E$71,"<="&$C32,'3_Fournisseurs'!$J$12:$J$71,">0")) -> 0 | F32: =D32-E32 -> 0 | G32: =G31+F32 -> 0
A33: S13 | B33: =C32+1 -> 46344 | C33: =B33+6 -> 46350 | D33: =IF($B33='0_Accueil'!$D$10,SUMIFS('2_Clients'!$I$12:$I$111,'2_Clients'!$D$12:$D$111,">0",'2_Clients'!$D$12:$D$111,"<="&$C33,'2_Clients'!$I$12:$I$111,">0"),SUMIFS('2_Clients'!$I$12:$I$111,'2_Clients'!$D$12:$D$111,">="&$B33,'2_Clients'!$D$12:$D$111,"<="&$C33,'2_Clients'!$I$12:$I$111,">0")) -> 0 | E33: =IF($B33='0_Accueil'!$D$10,SUMIFS('3_Fournisseurs'!$J$12:$J$71,'3_Fournisseurs'!$E$12:$E$71,">0",'3_Fournisseurs'!$E$12:$E$71,"<="&$C33,'3_Fournisseurs'!$J$12:$J$71,">0"),SUMIFS('3_Fournisseurs'!$J$12:$J$71,'3_Fournisseurs'!$E$12:$E$71,">="&$B33,'3_Fournisseurs'!$E$12:$E$71,"<="&$C33,'3_Fournisseurs'!$J$12:$J$71,">0")) -> 0 | F33: =D33-E33 -> 0 | G33: =G32+F33 -> 0
A36: ③ CASH À RISQUE — CLIENTS ET FOURNISSEURS
A37: Ancienneté clients | B37: Montant | C37: % encours | D37: Nb factures
A38: Non échues | B38: =SUMIFS('2_Clients'!$I$12:$I$111,'2_Clients'!$K$12:$K$111,"<=0",'2_Clients'!$I$12:$I$111,">0") -> 0 | C38: =IFERROR(B38/'2_Clients'!$M$7,0) -> 0 | D38: =COUNTIFS('2_Clients'!$K$12:$K$111,"<=0",'2_Clients'!$I$12:$I$111,">0") -> 0
A39: 1–30 jours | B39: =SUMIFS('2_Clients'!$I$12:$I$111,'2_Clients'!$K$12:$K$111,">0",'2_Clients'!$K$12:$K$111,"<=30",'2_Clients'!$I$12:$I$111,">0") -> 0 | C39: =IFERROR(B39/'2_Clients'!$M$7,0) -> 0 | D39: =COUNTIFS('2_Clients'!$K$12:$K$111,">0",'2_Clients'!$K$12:$K$111,"<=30",'2_Clients'!$I$12:$I$111,">0") -> 0
A40: 31–60 jours | B40: =SUMIFS('2_Clients'!$I$12:$I$111,'2_Clients'!$K$12:$K$111,">30",'2_Clients'!$K$12:$K$111,"<=60",'2_Clients'!$I$12:$I$111,">0") -> 0 | C40: =IFERROR(B40/'2_Clients'!$M$7,0) -> 0 | D40: =COUNTIFS('2_Clients'!$K$12:$K$111,">30",'2_Clients'!$K$12:$K$111,"<=60",'2_Clients'!$I$12:$I$111,">0") -> 0
A41: 61–90 jours | B41: =SUMIFS('2_Clients'!$I$12:$I$111,'2_Clients'!$K$12:$K$111,">60",'2_Clients'!$K$12:$K$111,"<=90",'2_Clients'!$I$12:$I$111,">0") -> 0 | C41: =IFERROR(B41/'2_Clients'!$M$7,0) -> 0 | D41: =COUNTIFS('2_Clients'!$K$12:$K$111,">60",'2_Clients'!$K$12:$K$111,"<=90",'2_Clients'!$I$12:$I$111,">0") -> 0
A42: Plus de 90 jours | B42: =SUMIFS('2_Clients'!$I$12:$I$111,'2_Clients'!$K$12:$K$111,">90",'2_Clients'!$I$12:$I$111,">0") -> 0 | C42: =IFERROR(B42/'2_Clients'!$M$7,0) -> 0 | D42: =COUNTIFS('2_Clients'!$K$12:$K$111,">90",'2_Clients'!$I$12:$I$111,">0") -> 0
A45: Risque fournisseurs | B45: Valeur | C45: Unité | D45: Lecture
A46: Dettes fournisseurs échues | B46: =SUMIFS('3_Fournisseurs'!$J$12:$J$71,'3_Fournisseurs'!$E$12:$E$71,">0",'3_Fournisseurs'!$E$12:$E$71,"<"&'0_Accueil'!$D$10,'3_Fournisseurs'!$J$12:$J$71,">0") -> 0 | C46: DH | D46: Sorties déjà exigibles
A47: Factures fournisseurs échues | B47: =COUNTIFS('3_Fournisseurs'!$E$12:$E$71,">0",'3_Fournisseurs'!$E$12:$E$71,"<"&'0_Accueil'!$D$10,'3_Fournisseurs'!$J$12:$J$71,">0") -> 0 | C47: factures | D47: Volume à traiter
A48: DPO pondéré | B48: ='3_Fournisseurs'!$M$2 -> 0 | C48: jours | D48: Délai réel
A49: Délai contractuel | B49: ='3_Fournisseurs'!$M$3 -> 0 | C49: jours | D49: Délai négocié
A50: Écart réel vs contrat | B50: ='3_Fournisseurs'!$M$4 -> 0 | C50: jours | D50: Positif = dépassement
...
